<?xml version="1.0" ?>
<robot name="base_link" xmlns:xacro="http://www.ros.org/wiki/xacro">

<xacro:include filename="$(find base_link_description)/urdf/materials.xacro" />
<xacro:include filename="$(find base_link_description)/urdf/base_link.trans" />
<xacro:include filename="$(find base_link_description)/urdf/base_link.gazebo" />
<link name="base_link">
  <inertial>
    <origin xyz="0.06305689638576689 0.00585843043883159 -0.023326240012378978" rpy="0 0 0"/>
    <mass value="0.2907900525200227"/>
    <inertia ixx="7.1e-05" iyy="4.1e-05" izz="6.9e-05" ixy="0.0" iyz="0.0" ixz="-0.0"/>
  </inertial>
  <visual>
    <origin xyz="0 0 0" rpy="0 0 0"/>
    <geometry>
      <mesh filename="package://base_link_description/meshes/base_link.stl" scale="0.001 0.001 0.001"/>
    </geometry>
    <material name="silver"/>
  </visual>
  <collision>
    <origin xyz="0 0 0" rpy="0 0 0"/>
    <geometry>
      <mesh filename="package://base_link_description/meshes/base_link.stl" scale="0.001 0.001 0.001"/>
    </geometry>
  </collision>
</link>

<link name="Component2_1">
  <inertial>
    <origin xyz="5.554096524362784e-08 -1.2621021338449223e-07 -2.401913897775998e-07" rpy="0 0 0"/>
    <mass value="7.583411966684051e-06"/>
    <inertia ixx="0.0" iyy="0.0" izz="0.0" ixy="0.0" iyz="0.0" ixz="0.0"/>
  </inertial>
  <visual>
    <origin xyz="-0.075387 -0.024972 0.035326" rpy="0 0 0"/>
    <geometry>
      <mesh filename="package://base_link_description/meshes/Component2_1.stl" scale="0.001 0.001 0.001"/>
    </geometry>
    <material name="silver"/>
  </visual>
  <collision>
    <origin xyz="-0.075387 -0.024972 0.035326" rpy="0 0 0"/>
    <geometry>
      <mesh filename="package://base_link_description/meshes/Component2_1.stl" scale="0.001 0.001 0.001"/>
    </geometry>
  </collision>
</link>

<link name="Component3_1">
  <inertial>
    <origin xyz="5.5585668540247823e-08 -1.2621021350592287e-07 -2.4001257658418096e-07" rpy="0 0 0"/>
    <mass value="7.583411966684036e-06"/>
    <inertia ixx="0.0" iyy="0.0" izz="0.0" ixy="-0.0" iyz="-0.0" ixz="-0.0"/>
  </inertial>
  <visual>
    <origin xyz="-0.075387 -0.024972 0.011326" rpy="0 0 0"/>
    <geometry>
      <mesh filename="package://base_link_description/meshes/Component3_1.stl" scale="0.001 0.001 0.001"/>
    </geometry>
    <material name="silver"/>
  </visual>
  <collision>
    <origin xyz="-0.075387 -0.024972 0.011326" rpy="0 0 0"/>
    <geometry>
      <mesh filename="package://base_link_description/meshes/Component3_1.stl" scale="0.001 0.001 0.001"/>
    </geometry>
  </collision>
</link>

<link name="Component5_1">
  <inertial>
    <origin xyz="0.006908962308009622 0.00011212641061179862 0.008233474394671621" rpy="0 0 0"/>
    <mass value="0.0021799380279681597"/>
    <inertia ixx="0.0" iyy="0.0" izz="0.0" ixy="-0.0" iyz="-0.0" ixz="-0.0"/>
  </inertial>
  <visual>
    <origin xyz="-0.075387 -0.024972 0.011326" rpy="0 0 0"/>
    <geometry>
      <mesh filename="package://base_link_description/meshes/Component5_1.stl" scale="0.001 0.001 0.001"/>
    </geometry>
    <material name="silver"/>
  </visual>
  <collision>
    <origin xyz="-0.075387 -0.024972 0.011326" rpy="0 0 0"/>
    <geometry>
      <mesh filename="package://base_link_description/meshes/Component5_1.stl" scale="0.001 0.001 0.001"/>
    </geometry>
  </collision>
</link>

<link name="Component7_1">
  <inertial>
    <origin xyz="0.006908962263306173 0.00011212641061190617 -0.008233954598638002" rpy="0 0 0"/>
    <mass value="0.0021799380279681584"/>
    <inertia ixx="0.0" iyy="0.0" izz="0.0" ixy="-0.0" iyz="0.0" ixz="0.0"/>
  </inertial>
  <visual>
    <origin xyz="-0.075387 -0.024972 0.035326" rpy="0 0 0"/>
    <geometry>
      <mesh filename="package://base_link_description/meshes/Component7_1.stl" scale="0.001 0.001 0.001"/>
    </geometry>
    <material name="silver"/>
  </visual>
  <collision>
    <origin xyz="-0.075387 -0.024972 0.035326" rpy="0 0 0"/>
    <geometry>
      <mesh filename="package://base_link_description/meshes/Component7_1.stl" scale="0.001 0.001 0.001"/>
    </geometry>
  </collision>
</link>

<link name="Component4_1">
  <inertial>
    <origin xyz="0.005373983182150363 0.00011212641061177434 -0.009308695996548717" rpy="0 0 0"/>
    <mass value="0.0021799380279681584"/>
    <inertia ixx="0.0" iyy="0.0" izz="0.0" ixy="-0.0" iyz="0.0" ixz="0.0"/>
  </inertial>
  <visual>
    <origin xyz="-0.088243 -0.027972 -0.003995" rpy="0 0 0"/>
    <geometry>
      <mesh filename="package://base_link_description/meshes/Component4_1.stl" scale="0.001 0.001 0.001"/>
    </geometry>
    <material name="silver"/>
  </visual>
  <collision>
    <origin xyz="-0.088243 -0.027972 -0.003995" rpy="0 0 0"/>
    <geometry>
      <mesh filename="package://base_link_description/meshes/Component4_1.stl" scale="0.001 0.001 0.001"/>
    </geometry>
  </collision>
</link>

<link name="Component6_1">
  <inertial>
    <origin xyz="0.010099953672244491 0.0001121264106118923 0.003676023429242954" rpy="0 0 0"/>
    <mass value="0.002179938027968158"/>
    <inertia ixx="0.0" iyy="0.0" izz="0.0" ixy="-0.0" iyz="-0.0" ixz="-0.0"/>
  </inertial>
  <visual>
    <origin xyz="-0.088243 -0.027972 0.050647" rpy="0 0 0"/>
    <geometry>
      <mesh filename="package://base_link_description/meshes/Component6_1.stl" scale="0.001 0.001 0.001"/>
    </geometry>
    <material name="silver"/>
  </visual>
  <collision>
    <origin xyz="-0.088243 -0.027972 0.050647" rpy="0 0 0"/>
    <geometry>
      <mesh filename="package://base_link_description/meshes/Component6_1.stl" scale="0.001 0.001 0.001"/>
    </geometry>
  </collision>
</link>

<link name="Component9_1">
  <inertial>
    <origin xyz="5.5624693601208364e-08 -0.0023356156130156375 0.0032698864895801295" rpy="0 0 0"/>
    <mass value="0.002698349766198897"/>
    <inertia ixx="0.0" iyy="0.0" izz="0.0" ixy="0.0" iyz="0.0" ixz="0.0"/>
  </inertial>
  <visual>
    <origin xyz="-0.075387 0.015528 0.011326" rpy="0 0 0"/>
    <geometry>
      <mesh filename="package://base_link_description/meshes/Component9_1.stl" scale="0.001 0.001 0.001"/>
    </geometry>
    <material name="silver"/>
  </visual>
  <collision>
    <origin xyz="-0.075387 0.015528 0.011326" rpy="0 0 0"/>
    <geometry>
      <mesh filename="package://base_link_description/meshes/Component9_1.stl" scale="0.001 0.001 0.001"/>
    </geometry>
  </collision>
</link>

<link name="Component8_1">
  <inertial>
    <origin xyz="5.550193991898933e-08 -0.0023356156130157416 -0.0032703666935461687" rpy="0 0 0"/>
    <mass value="0.002698349766198897"/>
    <inertia ixx="0.0" iyy="0.0" izz="0.0" ixy="-0.0" iyz="-0.0" ixz="0.0"/>
  </inertial>
  <visual>
    <origin xyz="-0.075387 0.015528 0.035326" rpy="0 0 0"/>
    <geometry>
      <mesh filename="package://base_link_description/meshes/Component8_1.stl" scale="0.001 0.001 0.001"/>
    </geometry>
    <material name="silver"/>
  </visual>
  <collision>
    <origin xyz="-0.075387 0.015528 0.035326" rpy="0 0 0"/>
    <geometry>
      <mesh filename="package://base_link_description/meshes/Component8_1.stl" scale="0.001 0.001 0.001"/>
    </geometry>
  </collision>
</link>

<link name="Component10_1">
  <inertial>
    <origin xyz="0.006133080263353546 -1.2608162179225668e-07 -0.004500240032792556" rpy="0 0 0"/>
    <mass value="0.009246517630484667"/>
    <inertia ixx="0.0" iyy="0.0" izz="0.0" ixy="0.0" iyz="-0.0" ixz="0.0"/>
  </inertial>
  <visual>
    <origin xyz="-0.075387 0.018028 -0.005174" rpy="0 0 0"/>
    <geometry>
      <mesh filename="package://base_link_description/meshes/Component10_1.stl" scale="0.001 0.001 0.001"/>
    </geometry>
    <material name="silver"/>
  </visual>
  <collision>
    <origin xyz="-0.075387 0.018028 -0.005174" rpy="0 0 0"/>
    <geometry>
      <mesh filename="package://base_link_description/meshes/Component10_1.stl" scale="0.001 0.001 0.001"/>
    </geometry>
  </collision>
</link>

<link name="Component11_1">
  <inertial>
    <origin xyz="0.006133080218650014 -1.2608162197613737e-07 -0.004500240211605874" rpy="0 0 0"/>
    <mass value="0.009246517630484665"/>
    <inertia ixx="0.0" iyy="0.0" izz="0.0" ixy="0.0" iyz="-0.0" ixz="0.0"/>
  </inertial>
  <visual>
    <origin xyz="-0.075387 0.018028 0.042826" rpy="0 0 0"/>
    <geometry>
      <mesh filename="package://base_link_description/meshes/Component11_1.stl" scale="0.001 0.001 0.001"/>
    </geometry>
    <material name="silver"/>
  </visual>
  <collision>
    <origin xyz="-0.075387 0.018028 0.042826" rpy="0 0 0"/>
    <geometry>
      <mesh filename="package://base_link_description/meshes/Component11_1.stl" scale="0.001 0.001 0.001"/>
    </geometry>
  </collision>
</link>

<link name="Component13_1">
  <inertial>
    <origin xyz="0.0034324596946620073 0.0027457971031129187 -0.0035002398933671516" rpy="0 0 0"/>
    <mass value="0.006403674888515739"/>
    <inertia ixx="0.0" iyy="0.0" izz="0.0" ixy="-0.0" iyz="0.0" ixz="-0.0"/>
  </inertial>
  <visual>
    <origin xyz="-0.090387 0.018028 -0.004174" rpy="0 0 0"/>
    <geometry>
      <mesh filename="package://base_link_description/meshes/Component13_1.stl" scale="0.001 0.001 0.001"/>
    </geometry>
    <material name="silver"/>
  </visual>
  <collision>
    <origin xyz="-0.090387 0.018028 -0.004174" rpy="0 0 0"/>
    <geometry>
      <mesh filename="package://base_link_description/meshes/Component13_1.stl" scale="0.001 0.001 0.001"/>
    </geometry>
  </collision>
</link>

<link name="Component12_1">
  <inertial>
    <origin xyz="0.003432459649958433 0.0027457971031127244 0.003499759927819472" rpy="0 0 0"/>
    <mass value="0.006403674888515739"/>
    <inertia ixx="0.0" iyy="0.0" izz="0.0" ixy="-0.0" iyz="0.0" ixz="0.0"/>
  </inertial>
  <visual>
    <origin xyz="-0.090387 0.018028 0.050826" rpy="0 0 0"/>
    <geometry>
      <mesh filename="package://base_link_description/meshes/Component12_1.stl" scale="0.001 0.001 0.001"/>
    </geometry>
    <material name="silver"/>
  </visual>
  <collision>
    <origin xyz="-0.090387 0.018028 0.050826" rpy="0 0 0"/>
    <geometry>
      <mesh filename="package://base_link_description/meshes/Component12_1.stl" scale="0.001 0.001 0.001"/>
    </geometry>
  </collision>
</link>

<joint name="Slider 13" type="prismatic">
  <origin xyz="0.075387 0.024972 -0.035326" rpy="0 0 0"/>
  <parent link="base_link"/>
  <child link="Component2_1"/>
  <axis xyz="-0.0 -1.0 0.0"/>
  <limit upper="0.0" lower="0.0" effort="100" velocity="100"/>
</joint>

<joint name="Slider 14" type="prismatic">
  <origin xyz="0.075387 0.024972 -0.011326" rpy="0 0 0"/>
  <parent link="base_link"/>
  <child link="Component3_1"/>
  <axis xyz="-0.0 -1.0 0.0"/>
  <limit upper="0.0" lower="0.0" effort="100" velocity="100"/>
</joint>

<joint name="Revolute 15" type="continuous">
  <origin xyz="0.0 0.0 0.0" rpy="0 0 0"/>
  <parent link="Component3_1"/>
  <child link="Component5_1"/>
  <axis xyz="-0.0 1.0 -0.0"/>
</joint>

<joint name="Revolute 16" type="continuous">
  <origin xyz="0.0 0.0 0.0" rpy="0 0 0"/>
  <parent link="Component2_1"/>
  <child link="Component7_1"/>
  <axis xyz="0.0 1.0 -0.0"/>
</joint>

<joint name="Revolute 17" type="continuous">
  <origin xyz="0.012856 0.003 0.015321" rpy="0 0 0"/>
  <parent link="Component5_1"/>
  <child link="Component4_1"/>
  <axis xyz="-0.0 1.0 -0.0"/>
</joint>

<joint name="Revolute 18" type="continuous">
  <origin xyz="0.012856 0.003 -0.015321" rpy="0 0 0"/>
  <parent link="Component7_1"/>
  <child link="Component6_1"/>
  <axis xyz="0.0 1.0 -0.0"/>
</joint>

<joint name="Revolute 19" type="continuous">
  <origin xyz="0.075387 -0.015528 -0.011326" rpy="0 0 0"/>
  <parent link="base_link"/>
  <child link="Component9_1"/>
  <axis xyz="0.0 1.0 -0.0"/>
</joint>

<joint name="Revolute 20" type="continuous">
  <origin xyz="0.075387 -0.015528 -0.035326" rpy="0 0 0"/>
  <parent link="base_link"/>
  <child link="Component8_1"/>
  <axis xyz="0.0 1.0 -0.0"/>
</joint>

<joint name="Revolute 21" type="continuous">
  <origin xyz="0.0 -0.0025 0.0165" rpy="0 0 0"/>
  <parent link="Component9_1"/>
  <child link="Component10_1"/>
  <axis xyz="0.0 0.0 1.0"/>
</joint>

<joint name="Revolute 22" type="continuous">
  <origin xyz="0.0 -0.0025 -0.0075" rpy="0 0 0"/>
  <parent link="Component8_1"/>
  <child link="Component11_1"/>
  <axis xyz="-0.0 -0.0 -1.0"/>
</joint>

<joint name="Revolute 23" type="continuous">
  <origin xyz="0.015 0.0 -0.001" rpy="0 0 0"/>
  <parent link="Component10_1"/>
  <child link="Component13_1"/>
  <axis xyz="-0.0 -0.0 -1.0"/>
</joint>

<joint name="Revolute 24" type="continuous">
  <origin xyz="0.015 0.0 -0.008" rpy="0 0 0"/>
  <parent link="Component11_1"/>
  <child link="Component12_1"/>
  <axis xyz="0.0 0.0 1.0"/>
</joint>

</robot>
